<?xml version="1.0" ?>
<sdf version="1.5">
  <model name="balloon_stick">
    <static>0</static>
    <link name="balloon_link">
      <gravity>0</gravity>
      <pose>0 0 5 0 0 0</pose>

      <inertial>
        <mass>0.1</mass>
        <inertia>
          <ixx>0.008611666666666669</ixx>
          <ixy>0</ixy>
          <ixz>0</ixz>
          <iyy>0.008611666666666669</iyy>
          <iyz>0</iyz>
          <izz>0.008611666666666669</izz>
        </inertia>
      </inertial>

      <visual name="balloon">
        <pose>0 0 0.25 0 0 0</pose>
        <geometry>
          <mesh>
            <uri>model://balloon_red/meshes/balonek.stl</uri>
          </mesh>
        </geometry>
        <material>
          <script>
            <uri>model://balloon_red/scripts</uri>
            <uri>model://balloon_red/materials/textures</uri>
            <name>BalloonRed/Balloon</name>
          </script>
        </material>
      </visual>

    </link>

    <link name="stick_link">
      <gravity>0</gravity>
      <pose>0 0 0 0 0 0</pose>
      
      <inertial>
        <mass>0.01</mass>
        <inertia>
          <ixx>0</ixx>
          <ixy>0</ixy>
          <ixz>0</ixz>
          <iyy>0</iyy>
          <iyz>0</iyz>
          <izz>0</izz>
        </inertia>
      </inertial>

    </link>

    <link name="anchor_link">
      <gravity>1</gravity>
      <pose>0 0 0 0 0 0</pose>
      
      <inertial>
        <mass>10</mass>
        <inertia>
          <ixx>0.08611666666666669</ixx>
          <ixy>0</ixy>
          <ixz>0</ixz>
          <iyy>0.08611666666666669</iyy>
          <iyz>0</iyz>
          <izz>0.08611666666666669</izz>
        </inertia>
      </inertial>

      <visual name="anchor">
        <pose>0 0 0 0 0 0</pose>
        <geometry>
          <cylinder>
            <radius>0.1</radius>
            <length>0.2</length>
          </cylinder>
        </geometry>
        <material>
          <script>
            <name>Gazebo/GazeboBlack</name>
          </script>
        </material>
      </visual>

      <collision name="anchor">
        <pose>0 0 0 0 0 0</pose>
        <geometry>
          <cylinder>
            <radius>0.1</radius>
            <length>0.2</length>
          </cylinder>
        </geometry>
      </collision>

    </link>

    <joint name="anchor_stick_joint" type="ball">
      <child>stick_link</child>
      <parent>anchor_link</parent>
    </joint>
    <joint name="stick_balloon_joint" type="ball">
      <child>balloon_link</child>
      <parent>stick_link</parent>
    </joint>
  </model>
</sdf>


